<?xml version="1.0" ?>
<!-- Note: Do NOT add a 'world' link here - it causes crashes in MoveIt Setup Assistant on WSL.
     Instead, use a virtual_joint in the SRDF to attach the robot to the world frame. -->
<robot name="lebai_lm3">
  <!-- link list -->
  <link name="base_link">
    <visual>
      <geometry>
        <mesh filename="../meshes/lm3_l1/visual/base_link.stl"/>
      </geometry>
      <material name="white">
        <color rgba="0.86 0.85 0.81 1.0"/>
      </material>
    </visual>
    <collision>
      <geometry>
        <mesh filename="../meshes/lm3_l1/collision/base_link.stl"/>
      </geometry>
    </collision>
  </link>
  <link name="link_1">
    <visual>
      <geometry>
        <mesh filename="../meshes/lm3_l1/visual/link1.stl"/>
      </geometry>
      <material name="white">
        <color rgba="0.86 0.85 0.81 1.0"/>
      </material>
    </visual>
    <collision>
      <geometry>
        <mesh filename="../meshes/lm3_l1/collision/link1.stl"/>
      </geometry>
    </collision>
    <inertial>
      <origin rpy="0.0 0.0 0.0" xyz="0.0 -0.004834 -0.08972"/>
      <mass value="2.31"/>
      <inertia ixx="0.0093" ixy="0.0" ixz="0.0" iyy="0.00913" iyz="0.0" izz="0.00303"/>
    </inertial>
  </link>
  <link name="link_2">
    <visual>
      <geometry>
        <mesh filename="../meshes/lm3_l1/visual/link2.stl"/>
      </geometry>
      <material name="white">
        <color rgba="0.86 0.85 0.81 1.0"/>
      </material>
    </visual>
    <collision>
      <geometry>
        <mesh filename="../meshes/lm3_l1/collision/link2.stl"/>
      </geometry>
    </collision>
    <inertial>
      <origin rpy="0.0 0.0 0.0" xyz="-0.18435 0.0 0.09428"/>
      <mass value="2.1612"/>
      <inertia ixx="0.0211" ixy="0.0" ixz="0.03767" iyy="0.1554" iyz="0.0" izz="0.13643"/>
    </inertial>
  </link>
  <link name="link_3">
    <visual>
      <geometry>
        <mesh filename="../meshes/lm3_l1/visual/link3.stl"/>
      </geometry>
      <material name="white">
        <color rgba="0.86 0.85 0.81 1.0"/>
      </material>
    </visual>
    <collision>
      <geometry>
        <mesh filename="../meshes/lm3_l1/collision/link3.stl"/>
      </geometry>
    </collision>
    <inertial>
      <origin rpy="0.0 0.0 0.0" xyz="-0.14386 0.0 0.01892"/>
      <mass value="1.8508"/>
      <inertia ixx="0.002519" ixy="0.0" ixz="0.00121" iyy="0.08222" iyz="0.0" izz="0.08138"/>
    </inertial>
  </link>
  <link name="link_4">
    <visual>
      <geometry>
        <mesh filename="../meshes/lm3_l1/visual/link4.stl"/>
      </geometry>
      <material name="white">
        <color rgba="0.86 0.85 0.81 1.0"/>
      </material>
    </visual>
    <collision>
      <geometry>
        <mesh filename="../meshes/lm3_l1/collision/link4.stl"/>
      </geometry>
    </collision>
    <inertial>
      <origin rpy="0.0 0.0 0.0" xyz="0.0 0.011 -0.03772"/>
      <mass value="0.93256"/>
      <inertia ixx="0.0032645" ixy="0.0" ixz="0.0" iyy="0.003061" iyz="0.0" izz="0.000866"/>
    </inertial>
  </link>
  <link name="link_5">
    <visual>
      <geometry>
        <mesh filename="../meshes/lm3_l1/visual/link5.stl"/>
      </geometry>
      <material name="white">
        <color rgba="0.86 0.85 0.81 1.0"/>
      </material>
    </visual>
    <collision>
      <geometry>
        <mesh filename="../meshes/lm3_l1/collision/link5.stl"/>
      </geometry>
    </collision>
    <inertial>
      <origin rpy="0.0 0.0 0.0" xyz="0.0 -0.011 -0.03772"/>
      <mass value="0.93256"/>
      <inertia ixx="0.0032645" ixy="0.0" ixz="0.0" iyy="0.003061" iyz="0.0" izz="0.000866"/>
    </inertial>
  </link>
  <link name="link_6">
    <visual>
      <geometry>
        <mesh filename="../meshes/lm3_l1/visual/link6.stl"/>
      </geometry>
      <material name="white">
        <color rgba="0.86 0.85 0.81 1.0"/>
      </material>
    </visual>
    <collision>
      <geometry>
        <mesh filename="../meshes/lm3_l1/collision/link6.stl"/>
      </geometry>
    </collision>
    <inertial>
      <origin rpy="0 0 0" xyz="0 0 -0.04882"/>
      <mass value="0.5782"/>
      <inertia ixx="0.001883" ixy="0.0" ixz="0.0" iyy="0.0018889" iyz="0.0" izz="0.000404"/>
    </inertial>
  </link>
  <!-- Note: Empty links crash MoveIt Setup Assistant on WSL. Adding tiny invisible geometry. -->
  <link name="base">
    <visual>
      <geometry>
        <box size="0.001 0.001 0.001"/>
      </geometry>
      <material name="invisible">
        <color rgba="0 0 0 0"/>
      </material>
    </visual>
    <collision>
      <geometry>
        <box size="0.001 0.001 0.001"/>
      </geometry>
    </collision>
  </link>
  <link name="tool0">
    <visual>
      <geometry>
        <box size="0.001 0.001 0.001"/>
      </geometry>
      <material name="invisible">
        <color rgba="0 0 0 0"/>
      </material>
    </visual>
    <collision>
      <geometry>
        <box size="0.001 0.001 0.001"/>
      </geometry>
    </collision>
  </link>
  <!-- end of link list -->
  <!-- joint list -->
  <joint name="joint_1" type="revolute">
    <parent link="base_link"/>
    <child link="link_1"/>
    <origin rpy="0.0 0.0 0.0" xyz="0.0 0.0 0.21583"/>
    <axis xyz="0 0 1"/>
    <limit effort="100" lower="-6.28" upper="6.28" velocity="3.14"/>
  </joint>
  <joint name="joint_2" type="revolute">
    <parent link="link_1"/>
    <child link="link_2"/>
    <origin rpy="1.570796327 0 0" xyz="0.0 0.0 0.0"/>
    <axis xyz="0 0 1"/>
    <limit effort="100" lower="-6.28" upper="6.28" velocity="3.14"/>
  </joint>
  <joint name="joint_3" type="revolute">
    <parent link="link_2"/>
    <child link="link_3"/>
    <origin rpy="0 0 0" xyz="-0.38 0 0"/>
    <axis xyz="0 0 1"/>
    <limit effort="100" lower="-6.28" upper="6.28" velocity="3.14"/>
  </joint>
  <joint name="joint_4" type="revolute">
    <parent link="link_3"/>
    <child link="link_4"/>
    <origin rpy="0 0 0" xyz="-0.355 0.0 0.12063"/>
    <axis xyz="0 0 1"/>
    <limit effort="100" lower="-6.28" upper="6.28" velocity="3.14"/>
  </joint>
  <joint name="joint_5" type="revolute">
    <parent link="link_4"/>
    <child link="link_5"/>
    <origin rpy="1.570796327 0 0" xyz="0 -0.09833 0"/>
    <axis xyz="0 0 1"/>
    <limit effort="5.5" lower="-6.28" upper="6.28" velocity="3.14"/>
  </joint>
  <joint name="joint_6" type="revolute">
    <parent link="link_5"/>
    <child link="link_6"/>
    <origin rpy="-1.570796327 0 0" xyz="0  0.08343 0"/>
    <axis xyz="0 0 1"/>
    <limit effort="4.6" lower="-6.28" upper="6.28" velocity="3.14"/>
  </joint>
  <joint name="joint_6-tool0" type="fixed">
    <parent link="link_6"/>
    <child link="tool0"/>
    <origin rpy="0 0 0" xyz="0 0 0"/>
  </joint>
  <joint name="base_link-base" type="fixed">
    <parent link="base_link"/>
    <child link="base"/>
    <origin rpy="0.0 0.0 0.0" xyz="0.0 0.0 0.0"/>
  </joint>
  <!-- end of joint list -->
  <!-- link list -->
  <link name="gripper_base_link">
    <visual>
      <geometry>
        <mesh filename="../meshes/gripper/visual/gripper_base.dae"/>
      </geometry>
      <material name="white">
        <color rgba="0.86 0.85 0.81 1.0"/>
      </material>
    </visual>
    <collision>
      <geometry>
        <mesh filename="../meshes/gripper/collision/gripper_base.dae"/>
      </geometry>
    </collision>
  </link>
  <link name="gripper_r_link1">
    <visual>
      <geometry>
        <mesh filename="../meshes/gripper/visual/gripper_link1.dae"/>
      </geometry>
      <material name="white">
        <color rgba="0.86 0.85 0.81 1.0"/>
      </material>
    </visual>
    <collision>
      <geometry>
        <mesh filename="../meshes/gripper/collision/gripper_link1.dae"/>
      </geometry>
    </collision>
  </link>
  <link name="gripper_r_link1_end_connection"/>
  <link name="gripper_r_link2">
    <visual>
      <geometry>
        <mesh filename="../meshes/gripper/visual/gripper_link2.dae"/>
      </geometry>
      <material name="white">
        <color rgba="0.86 0.85 0.81 1.0"/>
      </material>
    </visual>
    <collision>
      <geometry>
        <mesh filename="../meshes/gripper/collision/gripper_link2.dae"/>
      </geometry>
    </collision>
  </link>
  <link name="gripper_r_link_finger">
    <visual>
      <geometry>
        <mesh filename="../meshes/gripper/visual/gripper_link_finger.dae"/>
      </geometry>
      <material name="white">
        <color rgba="0.86 0.85 0.81 1.0"/>
      </material>
    </visual>
    <collision>
      <geometry>
        <mesh filename="../meshes/gripper/collision/gripper_link_finger.dae"/>
      </geometry>
    </collision>
  </link>
  <link name="gripper_r_link_finger_end_connection"/>
  <link name="gripper_l_link1">
    <visual>
      <geometry>
        <mesh filename="../meshes/gripper/visual/gripper_link1.dae"/>
      </geometry>
      <material name="white">
        <color rgba="0.86 0.85 0.81 1.0"/>
      </material>
    </visual>
    <collision>
      <geometry>
        <mesh filename="../meshes/gripper/collision/gripper_link1.dae"/>
      </geometry>
    </collision>
  </link>
  <link name="gripper_l_link1_end_connection"/>
  <link name="gripper_l_link2">
    <visual>
      <geometry>
        <mesh filename="../meshes/gripper/visual/gripper_link2.dae"/>
      </geometry>
      <material name="white">
        <color rgba="0.86 0.85 0.81 1.0"/>
      </material>
    </visual>
    <collision>
      <geometry>
        <mesh filename="../meshes/gripper/collision/gripper_link2.dae"/>
      </geometry>
    </collision>
  </link>
  <link name="gripper_l_link_finger">
    <visual>
      <geometry>
        <mesh filename="../meshes/gripper/visual/gripper_link_finger.dae"/>
      </geometry>
      <material name="white">
        <color rgba="0.86 0.85 0.81 1.0"/>
      </material>
    </visual>
    <collision>
      <geometry>
        <mesh filename="../meshes/gripper/collision/gripper_link_finger.dae"/>
      </geometry>
    </collision>
  </link>
  <link name="gripper_l_link_finger_end_connection"/>
  <link name="gripper_tip_midpoint_arm"/>
  <link name="gripper_tip_midpoint_counterarm"/>
  <link name="gripper_tip"/>
  <!-- end of link list -->
  <!-- joint list -->
  <joint name="gripper_r_joint1" type="revolute">
    <parent link="gripper_base_link"/>
    <child link="gripper_r_link1"/>
    <origin rpy="1.570796327 0.0 3.141592653589793" xyz="0.025 0.0 0.0856"/>
    <axis xyz="0 0 1"/>
    <limit effort="100" lower="0.0" upper="1.0471975511965976" velocity="1"/>
  </joint>
  <joint name="gripper_r_link1_end_connection_joint" type="fixed">
    <parent link="gripper_r_link1"/>
    <child link="gripper_r_link1_end_connection"/>
    <origin rpy="0.0 0.0 0.0" xyz="0.0 0.053 0.0"/>
  </joint>
  <joint name="gripper_r_joint2" type="revolute">
    <parent link="gripper_base_link"/>
    <child link="gripper_r_link2"/>
    <origin rpy="1.570796327 0 0" xyz="0.0115 0.0 0.1056"/>
    <axis xyz="0 0 1"/>
    <limit effort="100" lower="-1.0471975511965976" upper="0.0" velocity="1"/>
    <mimic joint="gripper_r_joint1" multiplier="-1.0" offset="0.0"/>
  </joint>
  <joint name="gripper_r_joint_finger" type="revolute">
    <parent link="gripper_r_link2"/>
    <child link="gripper_r_link_finger"/>
    <origin rpy="3.141592653589793 0 3.141592653589793" xyz="0.0 0.053 0.0"/>
    <axis xyz="0 0 1"/>
    <limit effort="100" lower="-1.0471975511965976" upper="0.0" velocity="1"/>
    <mimic joint="gripper_r_joint1" multiplier="-1.0" offset="0.0"/>
  </joint>
  <joint name="gripper_r_link_finger_end_connection_joint" type="revolute">
    <parent link="gripper_r_link_finger"/>
    <child link="gripper_r_link_finger_end_connection"/>
    <origin rpy="0.0 0.0 0.0" xyz="-0.0135 -0.02 0.0"/>
    <axis xyz="0 0 1"/>
    <limit effort="100" lower="0.0" upper="1.0471975511965976" velocity="1"/>
    <mimic joint="gripper_r_joint1" multiplier="1.0" offset="0.0"/>
  </joint>
  <joint name="gripper_l_joint1" type="revolute">
    <parent link="gripper_base_link"/>
    <child link="gripper_l_link1"/>
    <origin rpy="1.570796327 0.0 0.0" xyz="-0.025 0.0 0.0856"/>
    <axis xyz="0 0 1"/>
    <limit effort="100" lower="0.0" upper="1.0471975511965976" velocity="1"/>
    <mimic joint="gripper_r_joint1" multiplier="1.0" offset="0.0"/>
  </joint>
  <joint name="gripper_l_link1_end_connection_joint" type="fixed">
    <parent link="gripper_l_link1"/>
    <child link="gripper_l_link1_end_connection"/>
    <origin rpy="0.0 0.0 0.0" xyz="0.0 0.053 0.0"/>
  </joint>
  <joint name="gripper_l_joint2" type="revolute">
    <parent link="gripper_base_link"/>
    <child link="gripper_l_link2"/>
    <origin rpy="1.570796327 0 3.141592653589793" xyz="-0.0115 0.0 0.1056"/>
    <axis xyz="0 0 1"/>
    <limit effort="100" lower="-1.0471975511965976" upper="0.0" velocity="1"/>
    <mimic joint="gripper_r_joint1" multiplier="-1.0" offset="0.0"/>
  </joint>
  <joint name="gripper_l_joint_finger" type="revolute">
    <parent link="gripper_l_link2"/>
    <child link="gripper_l_link_finger"/>
    <origin rpy="3.141592653589793 0 3.141592653589793" xyz="0.0 0.053 0.0"/>
    <axis xyz="0 0 1"/>
    <limit effort="100" lower="-1.0471975511965976" upper="0.0" velocity="1"/>
    <mimic joint="gripper_r_joint1" multiplier="-1.0" offset="0.0"/>
  </joint>
  <joint name="gripper_l_link_finger_end_connection_joint" type="revolute">
    <parent link="gripper_l_link_finger"/>
    <child link="gripper_l_link_finger_end_connection"/>
    <origin rpy="0.0 0.0 0.0" xyz="-0.0135 -0.02 0.0"/>
    <axis xyz="0 0 1"/>
    <limit effort="100" lower="0.0" upper="1.0471975511965976" velocity="1"/>
    <mimic joint="gripper_r_joint1" multiplier="1.0" offset="0.0"/>
  </joint>
  <joint name="gripper_tip_midpoint_arm_joint" type="revolute">
    <parent link="gripper_base_link"/>
    <child link="gripper_tip_midpoint_arm"/>
    <origin rpy="0.0 0.0 0.0" xyz="0.0 0.0 0.1056"/>
    <axis xyz="0 1 0"/>
    <limit effort="100" lower="-3.141592653589793" upper="3.141592653589793" velocity="1"/>
    <mimic joint="gripper_r_joint1" multiplier="1.0" offset="0.0"/>
  </joint>
  <joint name="gripper_tip_midpoint_counterarm_joint" type="revolute">
    <parent link="gripper_tip_midpoint_arm"/>
    <child link="gripper_tip_midpoint_counterarm"/>
    <origin rpy="0.0 0.0 0.0" xyz="0.0 0.0 0.0265"/>
    <axis xyz="0 1 0"/>
    <limit effort="100" lower="-3.141592653589793" upper="3.141592653589793" velocity="1"/>
    <mimic joint="gripper_r_joint1" multiplier="-2.0" offset="0.0"/>
  </joint>
  <joint name="gripper_joint_tip" type="revolute">
    <parent link="gripper_tip_midpoint_counterarm"/>
    <child link="gripper_tip"/>
    <origin rpy="0.0 0.0 0.0" xyz="0.0 0.0 0.0265"/>
    <axis xyz="0 1 0"/>
    <limit effort="100" lower="-3.141592653589793" upper="3.141592653589793" velocity="1"/>
    <mimic joint="gripper_r_joint1" multiplier="1.0" offset="0.0"/>
  </joint>
  <joint name="fixed_gripper" type="fixed">
    <parent link="tool0"/>
    <child link="gripper_base_link"/>
  </joint>
</robot>
